Workbook

Sheet Read me
A1: PAMOJA simplified financial model - v0.4 (draft)
A2: How $24m flows TAMISEMI -> Lenders -> CMGs as loans, and back as repayments.
A5: HOW TO USE
A6: 1. Change the yellow cells with blue numbers only. Everything else is a formula.
A7: 2. Inputs: fund size, lending rules, lending timing and the split of interest.
A8: 3. Districts: CMG numbers, savings and loan size per LGA.
A9: 4. Monthly cycle: when loans go out and come back over 24 months (year 1 lending, year 2 run-off).
A10: 5. Fund flow: totals for all loans made in the year, with a check that the corpus is restored.
A11: 6. Open questions: things to settle. Glossary: acronyms and terms.
A13: IMPORTANT
A14: - All district data and rates are DUMMY placeholders. Replace them with real figures.
A15: - The split of interest is a first guess to confirm.
... A66: - Exchange rate (TZS / USD) and inflation.

Sheet Inputs
A1: Inputs
A2: Yellow cells are inputs. Dummy values - replace with agreed figures.
A4: Item | B4: Value | C4: Unit | D4: Note
A5: FUND
A6: Total PAMOJA fund | B6: 24000000 | C6: USD | D6: From TAMISEMI
A7: Lender incentives (set aside) | B7: 2000000 | C7: USD | D7: Not lent out
A8: CMG incentives (set aside) | B8: 2000000 | C8: USD | D8: Not lent out
A9: Lending corpus | B9: =B6-B7-B8 | C9: USD | D9: Money available to lend
A10: LENDING RULES
A11: Maximum Loan:Savings ratio | B11: 0.5 | C11: x | D11: Loan must not exceed this x CMG savings
A12: Interest rate (flat, per year) | B12: 0.18 | C12: % | D12: Placeholder; must be at or below TAMISEMI ceiling
A13: Maximum loan tenure | B13: 12 | C13: months | D13: Policy limit
A14: Loan term used in the model | B14: 6 | C14: months | D14: Must be 1 to the maximum tenure
A15: Check: term within maximum | B15: =IF(AND(B14>=1,B14<=B13),"OK","ERROR: term above maximum tenure")
A16: Portfolio default rate (budget) | B16: 0.05 | C16: % | D16: % of principal lent that is not repaid
A17: LENDING TIMING (across the cycle)
A18: Last month lenders can make new loans | B18: 12 | C18: month | D18: 1 to 12. Spread of new loans is set on 'Monthly cycle'
A19: % of principal repaid that is lent out again | B19: 0 | C19: % | D19: 0% = no re-lending (see question 4)
A20: Latest month to lend if all cash must be back by month 12 | B20: =MAX(0,12-B14) | C20: month | D20: 0 means only at the very start of the year
A21: SPLIT OF INTEREST COLLECTED
A22: Default budget (loss reserve) | B22: 0.3 | C22: % | D22: Returned to fund to cover defaults
A23: TAMISEMI share of interest | B23: 0.1 | C23: % | D23: Placeholder
A24: Region service fee | B24: 0.05 | C24: % | D24: Placeholder
A25: LGA service fee | B25: 0.05 | C25: % | D25: Placeholder
A26: Lender margin (remainder) | B26: =1-SUM(B22:B25) | C26: % | D26: What is left for the lender
A27: Check: split adds to 100% or less | B27: =IF(B26>=0,"OK","ERROR: over 100%")
A28: PRINCIPAL SETTLEMENT AND RISK SHARE
A29: TAMISEMI share of repaid principal | B29: 1 | C29: % | D29: Share of every repaid instalment returned to the TAMISEMI corpus
A30: Lender share of repaid principal (remainder) | B30: =1-B29 | C30: % | D30: Kept by the lender; computed from the TAMISEMI share above
A31: TAMISEMI risk share of defaults | B31: 0.5 | C31: % | D31: Share of every default TAMISEMI absorbs against the corpus. Placeholder - see question 12
A32: Lender risk share of defaults (remainder) | B32: =1-B31 | C32: % | D32: The lender's own loss on a default; computed from the TAMISEMI risk share above

Sheet Districts
A1: Allocation by district (LGA)
A2: Dummy data. Add real LGAs in the yellow cells; up to 20 rows. Allocates the first round of lending only.
A4: District (LGA) | B4: Number of CMGs | C4: Average savings per CMG (USD) | D4: Average loan asked per CMG (USD) | E4: Loan cap per CMG = savings x ratio | F4: Loan per CMG (smaller of the two) | G4: Loan:Savings ratio used | H4: Demand (USD) | I4: Allocation (USD) | J4: Share of corpus
A5: District A | B5: 2500 | C5: 4000 | D5: 2500 | E5: =IF(B5="","",C5*Inputs!$B$11) | F5: =IF(B5="","",MIN(D5,E5)) | G5: =IF(B5="","",F5/C5) | H5: =IF(B5="",0,B5*F5) | I5: =IF(B5="",0,H5*$B$28) | J5: =IF(B5="","",I5/Inputs!$B$9)
A6: District B | B6: 1800 | C6: 3000 | D6: 2000 | E6: =IF(B6="","",C6*Inputs!$B$11) | F6: =IF(B6="","",MIN(D6,E6)) | G6: =IF(B6="","",F6/C6) | H6: =IF(B6="",0,B6*F6) | I6: =IF(B6="",0,H6*$B$28) | J6: =IF(B6="","",I6/Inputs!$B$9)
A7: District C | B7: 3200 | C7: 5000 | D7: 3000 | E7: =IF(B7="","",C7*Inputs!$B$11) | F7: =IF(B7="","",MIN(D7,E7)) | G7: =IF(B7="","",F7/C7) | H7: =IF(B7="",0,B7*F7) | I7: =IF(B7="",0,H7*$B$28) | J7: =IF(B7="","",I7/Inputs!$B$9)
A8: District D | B8: 1500 | C8: 3500 | D8: 1500 | E8: =IF(B8="","",C8*Inputs!$B$11) | F8: =IF(B8="","",MIN(D8,E8)) | G8: =IF(B8="","",F8/C8) | H8: =IF(B8="",0,B8*F8) | I8: =IF(B8="",0,H8*$B$28) | J8: =IF(B8="","",I8/Inputs!$B$9)
A9: District E | B9: 2000 | C9: 4500 | D9: 2500 | E9: =IF(B9="","",C9*Inputs!$B$11) | F9: =IF(B9="","",MIN(D9,E9)) | G9: =IF(B9="","",F9/C9) | H9: =IF(B9="",0,B9*F9) | I9: =IF(B9="",0,H9*$B$28) | J9: =IF(B9="","",I9/Inputs!$B$9)
E10: =IF(B10="","",C10*Inputs!$B$11) | F10: =IF(B10="","",MIN(D10,E10)) | G10: =IF(B10="","",F10/C10) | H10: =IF(B10="",0,B10*F10) | I10: =IF(B10="",0,H10*$B$28) | J10: =IF(B10="","",I10/Inputs!$B$9)
E11: =IF(B11="","",C11*Inputs!$B$11) | F11: =IF(B11="","",MIN(D11,E11)) | G11: =IF(B11="","",F11/C11) | H11: =IF(B11="",0,B11*F11) | I11: =IF(B11="",0,H11*$B$28) | J11: =IF(B11="","",I11/Inputs!$B$9)
E12: =IF(B12="","",C12*Inputs!$B$11) | F12: =IF(B12="","",MIN(D12,E12)) | G12: =IF(B12="","",F12/C12) | H12: =IF(B12="",0,B12*F12) | I12: =IF(B12="",0,H12*$B$28) | J12: =IF(B12="","",I12/Inputs!$B$9)
E13: =IF(B13="","",C13*Inputs!$B$11) | F13: =IF(B13="","",MIN(D13,E13)) | G13: =IF(B13="","",F13/C13) | H13: =IF(B13="",0,B13*F13) | I13: =IF(B13="",0,H13*$B$28) | J13: =IF(B13="","",I13/Inputs!$B$9)
E14: =IF(B14="","",C14*Inputs!$B$11) | F14: =IF(B14="","",MIN(D14,E14)) | G14: =IF(B14="","",F14/C14) | H14: =IF(B14="",0,B14*F14) | I14: =IF(B14="",0,H14*$B$28) | J14: =IF(B14="","",I14/Inputs!$B$9)
E15: =IF(B15="","",C15*Inputs!$B$11) | F15: =IF(B15="","",MIN(D15,E15)) | G15: =IF(B15="","",F15/C15) | H15: =IF(B15="",0,B15*F15) | I15: =IF(B15="",0,H15*$B$28) | J15: =IF(B15="","",I15/Inputs!$B$9)
E16: =IF(B16="","",C16*Inputs!$B$11) | F16: =IF(B16="","",MIN(D16,E16)) | G16: =IF(B16="","",F16/C16) | H16: =IF(B16="",0,B16*F16) | I16: =IF(B16="",0,H16*$B$28) | J16: =IF(B16="","",I16/Inputs!$B$9)
E17: =IF(B17="","",C17*Inputs!$B$11) | F17: =IF(B17="","",MIN(D17,E17)) | G17: =IF(B17="","",F17/C17) | H17: =IF(B17="",0,B17*F17) | I17: =IF(B17="",0,H17*$B$28) | J17: =IF(B17="","",I17/Inputs!$B$9)
E18: =IF(B18="","",C18*Inputs!$B$11) | F18: =IF(B18="","",MIN(D18,E18)) | G18: =IF(B18="","",F18/C18) | H18: =IF(B18="",0,B18*F18) | I18: =IF(B18="",0,H18*$B$28) | J18: =IF(B18="","",I18/Inputs!$B$9)
E19: =IF(B19="","",C19*Inputs!$B$11) | F19: =IF(B19="","",MIN(D19,E19)) | G19: =IF(B19="","",F19/C19) | H19: =IF(B19="",0,B19*F19) | I19: =IF(B19="",0,H19*$B$28) | J19: =IF(B19="","",I19/Inputs!$B$9)
E20: =IF(B20="","",C20*Inputs!$B$11) | F20: =IF(B20="","",MIN(D20,E20)) | G20: =IF(B20="","",F20/C20) | H20: =IF(B20="",0,B20*F20) | I20: =IF(B20="",0,H20*$B$28) | J20: =IF(B20="","",I20/Inputs!$B$9)
E21: =IF(B21="","",C21*Inputs!$B$11) | F21: =IF(B21="","",MIN(D21,E21)) | G21: =IF(B21="","",F21/C21) | H21: =IF(B21="",0,B21*F21) | I21: =IF(B21="",0,H21*$B$28) | J21: =IF(B21="","",I21/Inputs!$B$9)
... E24: =IF(B24="","",C24*Inputs!$B$11) | F24: =IF(B24="","",MIN(D24,E24)) | G24: =IF(B24="","",F24/C24) | H24: =IF(B24="",0,B24*F24) | I24: =IF(B24="",0,H24*$B$28) | J24: =IF(B24="","",I24/Inputs!$B$9)
A25: TOTAL | B25: =SUM(B5:B24) | H25: =SUM(H5:H24) | I25: =SUM(I5:I24) | J25: =SUM(J5:J24)
A27: Lending corpus | B27: =Inputs!$B$9
A28: Scale factor (1 = full demand met) | B28: =IF(H25=0,0,MIN(1,B27/H25))
A29: Corpus not used | B29: =B27-I25
A30: Demand not met | B30: =H25-I25

Sheet Fund flow
A1: Fund flow: all loans made in year 1, until they close
A2: TAMISEMI -> Lenders -> CMGs -> back. All formulas; totals come from 'Monthly cycle'.
A4: Step | B4: Amount (USD) | C4: From -> To | D4: How it is worked out
A5: 1. MONEY OUT
A6: Total PAMOJA fund | B6: =Inputs!$B$6 | C6: TAMISEMI
A7: Lender incentives set aside | B7: =Inputs!$B$7 | C7: TAMISEMI -> Lenders | D7: Paid later, not lent
A8: CMG incentives set aside | B8: =Inputs!$B$8 | C8: TAMISEMI -> CMGs | D8: Paid later, not lent
A9: Advances to lenders (new loans from corpus) | B9: ='Monthly cycle'!$Z$8 | C9: TAMISEMI -> Lenders | D9: Sum over the months
A10: Corpus not lent (returned) | B10: =Inputs!$B$9-B9 | C10: Lenders -> TAMISEMI | D10: Unused advance
A11: Repayments lent out again | B11: ='Monthly cycle'!$Z$9 | C11: Lenders -> CMGs | D11: Re-lending
A12: Total loans to CMGs | B12: =B9+B11 | C12: Lenders -> CMGs
A13: 2. MONEY BACK FROM CMGs
A14: Principal defaulted | B14: =B12*Inputs!$B$16 | D14: Loans x default rate
A15: Principal repaid by CMGs (gross) | B15: ='Monthly cycle'!$Z$12 | C15: CMGs -> Lenders | D15: Loans - defaults
A16: TAMISEMI's share of repaid principal | B16: ='Monthly cycle'!$Z$15 | C16: Lenders -> TAMISEMI | D16: Repaid gross x TAMISEMI share of repaid principal
A17: Kept by the lender (repaid principal not returned) | B17: =B15-B16 | C17: Kept by lenders | D17: Repaid gross x lender share
A18: Interest collected | B18: ='Monthly cycle'!$Z$13 | C18: CMGs -> Lenders | D18: Flat: repaid x rate x term/12
A19: Total repayments | B19: =B15+B18 | C19: CMGs -> Lenders
A20: 3. SPLIT OF INTEREST
A21: Default budget (loss reserve) | B21: =B18*Inputs!$B$22 | C21: Lenders -> TAMISEMI
A22: TAMISEMI share of interest | B22: =B18*Inputs!$B$23 | C22: Lenders -> TAMISEMI
A23: Region service fee | B23: =B18*Inputs!$B$24 | C23: -> Region
A24: LGA service fee | B24: =B18*Inputs!$B$25 | C24: -> LGA
A25: Lender margin (from interest) | B25: =B18*Inputs!$B$26 | C25: Kept by lenders | D25: Remainder
A26: 4. RISK SHARE OF DEFAULTS
A27: TAMISEMI's risk share of defaults (absorbed by TAMISEMI) | B27: =B14*Inputs!$B$31 | C27: Loss to TAMISEMI | D27: Defaulted principal x TAMISEMI risk share
A28: Lender's risk share of defaults (the lender's own loss) | B28: =B14*Inputs!$B$32 | C28: Loss to lender | D28: Defaulted principal x lender risk share
A29: Lender's risk-share compensation paid into the fund | B29: ='Monthly cycle'!$Z$16 | C29: Lenders -> TAMISEMI | D29: Should equal the lender's risk share above
A30: Lender's net result (margin - own risk share - principal kept) | B30: =B25-B28+B17 | D30: Whether lending is worth it for the lender
A31: 5. CORPUS CHECK (after all loans close)
A32: Corpus at start | B32: =Inputs!$B$9
A33: Less: TAMISEMI's risk share of defaults | B33: =-B27
A34: Less: repaid principal kept by the lender | B34: =-B17
A35: Plus default budget added back | B35: =B21 | D35: Covers TAMISEMI's risk share of defaults
A36: Corpus at end | B36: =B32+B33+B34+B35
A37: Gap (end - start) | B37: =B36-B32 | D37: Negative = corpus NOT restored
A38: Result | B38: =IF(B37>=-0.5,"Corpus restored","Corpus NOT restored - raise interest share for defaults or rate")
A39: Default budget needed (% of interest) | B39: =IF(B18=0,0,B27/B18) | D39: Minimum share of interest to cover TAMISEMI's risk share of defaults
A40: Break-even default rate | B40: =Inputs!$B$22*Inputs!$B$12*Inputs!$B$14/12/(Inputs!$B$31+Inputs!$B$22*Inputs!$B$12*Inputs!$B$14/12) | D40: Highest default rate the current split and risk share can cover | F40: Chart data (auto - do not edit)
A41: Check: matches month-24 cash on 'Monthly cycle' | B41: =IF(ABS(B36-'Monthly cycle'!Y18)<1,"OK","ERROR") | F41: Money not lent (returned to TAMISEMI) | G41: =B10
...

Sheet Monthly cycle
A1: Monthly cycle (24 months: year 1 lending, year 2 run-off)
A2: Enter the % of the allocated amount lent as NEW loans each month (yellow, months 1-12). Repayments are equal monthly instalments over the loan term.
A4: Line | B4: M1 | C4: M2 | D4: M3 | E4: M4 | F4: M5 | G4: M6 | H4: M7 | I4: M8 | J4: M9 | K4: M10 | L4: M11 | M4: M12 | N4: M13 | O4: M14 | P4: M15 | Q4: M16 | R4: M17 | S4: M18 | T4: M19 | U4: M20 | V4: M21 | W4: M22 | X4: M23 | Y4: M24 | Z4: Total
A5: Month number | B5: 1 | C5: 2 | D5: 3 | E5: 4 | F5: 5 | G5: 6 | H5: 7 | I5: 8 | J5: 9 | K5: 10 | L5: 11 | M5: 12 | N5: 13 | O5: 14 | P5: 15 | Q5: 16 | R5: 17 | S5: 18 | T5: 19 | U5: 20 | V5: 21 | W5: 22 | X5: 23 | Y5: 24
A6: Year | B6: 1 | C6: 1 | D6: 1 | E6: 1 | F6: 1 | G6: 1 | H6: 1 | I6: 1 | J6: 1 | K6: 1 | L6: 1 | M6: 1 | N6: 2 | O6: 2 | P6: 2 | Q6: 2 | R6: 2 | S6: 2 | T6: 2 | U6: 2 | V6: 2 | W6: 2 | X6: 2 | Y6: 2
A7: % of allocation lent as NEW loans this month | B7: 0.25 | C7: 0.2 | D7: 0.15 | E7: 0.1 | F7: 0.1 | G7: 0.1 | H7: 0.05 | I7: 0.05 | J7: 0 | K7: 0 | L7: 0 | M7: 0 | N7: 0 | O7: 0 | P7: 0 | Q7: 0 | R7: 0 | S7: 0 | T7: 0 | U7: 0 | V7: 0 | W7: 0 | X7: 0 | Y7: 0 | Z7: =SUM(B7:M7)
A8: New loans from the corpus | B8: =IF(B$5<=Inputs!$B$18,B7*Districts!$I$25,0) | C8: =IF(C$5<=Inputs!$B$18,C7*Districts!$I$25,0) | D8: =IF(D$5<=Inputs!$B$18,D7*Districts!$I$25,0) | E8: =IF(E$5<=Inputs!$B$18,E7*Districts!$I$25,0) | F8: =IF(F$5<=Inputs!$B$18,F7*Districts!$I$25,0) | G8: =IF(G$5<=Inputs!$B$18,G7*Districts!$I$25,0) | H8: =IF(H$5<=Inputs!$B$18,H7*Districts!$I$25,0) | I8: =IF(I$5<=Inputs!$B$18,I7*Districts!$I$25,0) | ... Y8: =IF(Y$5<=Inputs!$B$18,Y7*Districts!$I$25,0) | Z8: =SUM(B8:Y8)
A9: Re-lent repayments | B9: =0 | C9: =IF(C$5<=Inputs!$B$18,B12*Inputs!$B$19,0) | D9: =IF(D$5<=Inputs!$B$18,C12*Inputs!$B$19,0) | E9: =IF(E$5<=Inputs!$B$18,D12*Inputs!$B$19,0) | F9: =IF(F$5<=Inputs!$B$18,E12*Inputs!$B$19,0) | G9: =IF(G$5<=Inputs!$B$18,F12*Inputs!$B$19,0) | H9: =IF(H$5<=Inputs!$B$18,G12*Inputs!$B$19,0) | I9: =IF(I$5<=Inputs!$B$18,H12*Inputs!$B$19,0) | J9: =IF(J$5<=Inputs!$B$18,I12*Inputs!$B$19,0) | ... Y9: =IF(Y$5<=Inputs!$B$18,X12*Inputs!$B$19,0) | Z9: =SUM(B9:Y9)
A10: Total loans made this month | B10: =B8+B9 | C10: =C8+C9 | D10: =D8+D9 | E10: =E8+E9 | F10: =F8+F9 | G10: =G8+G9 | H10: =H8+H9 | I10: =I8+I9 | ... Y10: =Y8+Y9 | Z10: =SUM(B10:Y10)
A11: Principal due | B11: =0 | C11: =SUMIFS($B10:B10,$B$5:B$5,">="&(C$5-Inputs!$B$14))/Inputs!$B$14 | D11: =SUMIFS($B10:C10,$B$5:C$5,">="&(D$5-Inputs!$B$14))/Inputs!$B$14 | E11: =SUMIFS($B10:D10,$B$5:D$5,">="&(E$5-Inputs!$B$14))/Inputs!$B$14 | F11: =SUMIFS($B10:E10,$B$5:E$5,">="&(F$5-Inputs!$B$14))/Inputs!$B$14 | G11: =SUMIFS($B10:F10,$B$5:F$5,">="&(G$5-Inputs!$B$14))/Inputs!$B$14 | H11: =SUMIFS($B10:G10,$B$5:G$5,">="&(H$5-Inputs!$B$14))/Inputs!$B$14 | I11: =SUMIFS($B10:H10,$B$5:H$5,">="&(I$5-Inputs!$B$14))/Inputs!$B$14 | J11: =SUMIFS($B10:I10,$B$5:I$5,">="&(J$5-Inputs!$B$14))/Inputs!$B$14 | ... Y11: =SUMIFS($B10:X10,$B$5:X$5,">="&(Y$5-Inputs!$B$14))/Inputs!$B$14 | Z11: =SUM(B11:Y11)
A12: Principal repaid by CMGs (gross, after defaults) | B12: =B11*(1-Inputs!$B$16) | C12: =C11*(1-Inputs!$B$16) | D12: =D11*(1-Inputs!$B$16) | E12: =E11*(1-Inputs!$B$16) | F12: =F11*(1-Inputs!$B$16) | G12: =G11*(1-Inputs!$B$16) | H12: =H11*(1-Inputs!$B$16) | I12: =I11*(1-Inputs!$B$16) | ... Y12: =Y11*(1-Inputs!$B$16) | Z12: =SUM(B12:Y12)
A13: Interest collected | B13: =B12*Inputs!$B$12/12*Inputs!$B$14 | C13: =C12*Inputs!$B$12/12*Inputs!$B$14 | D13: =D12*Inputs!$B$12/12*Inputs!$B$14 | E13: =E12*Inputs!$B$12/12*Inputs!$B$14 | F13: =F12*Inputs!$B$12/12*Inputs!$B$14 | G13: =G12*Inputs!$B$12/12*Inputs!$B$14 | H13: =H12*Inputs!$B$12/12*Inputs!$B$14 | I13: =I12*Inputs!$B$12/12*Inputs!$B$14 | ... Y13: =Y12*Inputs!$B$12/12*Inputs!$B$14 | Z13: =SUM(B13:Y13)
A14: Default budget returned to fund | B14: =B13*Inputs!$B$22 | C14: =C13*Inputs!$B$22 | D14: =D13*Inputs!$B$22 | E14: =E13*Inputs!$B$22 | F14: =F13*Inputs!$B$22 | G14: =G13*Inputs!$B$22 | H14: =H13*Inputs!$B$22 | I14: =I13*Inputs!$B$22 | ... Y14: =Y13*Inputs!$B$22 | Z14: =SUM(B14:Y14)
A15: TAMISEMI's share of repaid principal (to fund cash) | B15: =B12*Inputs!$B$29 | C15: =C12*Inputs!$B$29 | D15: =D12*Inputs!$B$29 | E15: =E12*Inputs!$B$29 | F15: =F12*Inputs!$B$29 | G15: =G12*Inputs!$B$29 | H15: =H12*Inputs!$B$29 | I15: =I12*Inputs!$B$29 | ... Y15: =Y12*Inputs!$B$29 | Z15: =SUM(B15:Y15)
A16: Lender's risk-share compensation for defaults (to fund cash) | B16: =(B11-B12)*Inputs!$B$32 | C16: =(C11-C12)*Inputs!$B$32 | D16: =(D11-D12)*Inputs!$B$32 | E16: =(E11-E12)*Inputs!$B$32 | F16: =(F11-F12)*Inputs!$B$32 | G16: =(G11-G12)*Inputs!$B$32 | H16: =(H11-H12)*Inputs!$B$32 | I16: =(I11-I12)*Inputs!$B$32 | ... Y16: =(Y11-Y12)*Inputs!$B$32 | Z16: =SUM(B16:Y16)
A17: Loans outstanding (end of month) | B17: =0+B10-B11 | C17: =B17+C10-C11 | D17: =C17+D10-D11 | E17: =D17+E10-E11 | F17: =E17+F10-F11 | G17: =F17+G10-G11 | H17: =G17+H10-H11 | I17: =H17+I10-I11 | J17: =I17+J10-J11 | ... Y17: =X17+Y10-Y11
A18: Fund cash on hand (end of month) | B18: =Inputs!$B$9-B10+B15+B16+B14 | C18: =B18-C10+C15+C16+C14 | D18: =C18-D10+D15+D16+D14 | E18: =D18-E10+E15+E16+E14 | F18: =E18-F10+F15+F16+F14 | G18: =F18-G10+G15+G16+G14 | H18: =G18-H10+H15+H16+H14 | I18: =H18-I10+I15+I16+I14 | J18: =I18-J10+J15+J16+J14 | ... Y18: =X18-Y10+Y15+Y16+Y14
A19: Cash + loans outstanding | B19: =B18+B17 | C19: =C18+C17 | D19: =D18+D17 | E19: =E18+E17 | F19: =F18+F17 | G19: =G18+G17 | H19: =H18+H17 | I19: =I18+I17 | ... Y19: =Y18+Y17
A20: (helper) month if cash is back to corpus | B20: =IF(B18>=Inputs!$B$9-0.5,B5,999) | C20: =IF(C18>=Inputs!$B$9-0.5,C5,999) | D20: =IF(D18>=Inputs!$B$9-0.5,D5,999) | E20: =IF(E18>=Inputs!$B$9-0.5,E5,999) | F20: =IF(F18>=Inputs!$B$9-0.5,F5,999) | G20: =IF(G18>=Inputs!$B$9-0.5,G5,999) | H20: =IF(H18>=Inputs!$B$9-0.5,H5,999) | I20: =IF(I18>=Inputs!$B$9-0.5,I5,999) | ... Y20: =IF(Y18>=Inputs!$B$9-0.5,Y5,999)
A22: YEAR-END SNAPSHOT (end of month 12)
A23: Fund cash on hand at month 12 | B23: =M18
A24: Money still out on loan at month 12 (repaid in year 2) | B24: =M17
A25: Cash + loans still out | B25: =M19
A26: Share of corpus back as cash at month 12 | B26: =M18/Inputs!$B$9
A27: Total loans made in year 1 (incl. re-lending) | B27: =SUM(B10:M10)
A28: Times the corpus was lent in year 1 (turnover) | B28: =SUM(B10:M10)/Inputs!$B$9
A29: First month the corpus is fully back as cash | B29: =IF(MIN(B20:Y20)=999,"Not within 24 months (defaults not covered)",MIN(B20:Y20))
A30: Fund cash at month 24 (all loans closed) | B30: =Y18
A31: Check: new-loan % adds to 100% | B31: =IF(ABS(Z7-1)<0.0001,"OK","ERROR: adjust row 7")
A32: Check: no new loans after the last lending month | B32: =IF(SUMPRODUCT((B5:M5>Inputs!$B$18)*B7:M7)>0,"WARNING: some % is after the last lending month and is ignored","OK")
A34: Note: fund cash counts TAMISEMI's share of repaid principal, the lender's risk-share compensation for defaults, and the default-budget share of interest. Interest shares also go to TAMISEMI, the region, the LGA and the lender; any repaid principal kept by the lender does not come back to the fund. The thick line marks year end.

Sheet Open questions
A1: Open questions
A2: To settle before the model uses real figures.
A4: # | B4: Question | C4: Why it matters | D4: Added in | E4: Answer
A5: 1 | B5: Is the Loan:Savings cap on the loan itself (loan must not exceed 0.5 x the CMG's savings)? | C5: Sets the loan cap per CMG on the Districts sheet. | D5: v0.1
A6: 2 | B6: Is interest flat or on the reducing balance? What is TAMISEMI's interest ceiling? | C6: Drives all interest income, and so the default budget. | D6: v0.1
A7: 3 | B7: Are the TAMISEMI, region and LGA amounts a % of interest, or a % of the loan amount? | C7: Changes how much interest is left for the default budget and the lender. | D7: v0.1
A8: 4 | B8: Can repayments be lent out again in the same year? If yes, to whom: new CMGs or second loans to the same CMGs? | C8: Re-lending raises total lending but ties money up longer; the Districts sheet only allocates the first round. | D8: v0.1
A9: 5 | B9: Are the $2m lender and $2m CMG incentive pots paid in full each year, or spread over several years? | C9: Decides whether the corpus stays at $20m every year. | D9: v0.1
A10: 6 | B10: When does TAMISEMI's annual cycle end (e.g. financial year July-June)? At that date, must the corpus be back as CASH, or can loans still running count? | C10: With lending across the cycle and tenures up to 12 months, some money is always out on loan at year end. | D10: v0.2
A11: 7 | B11: Do CMG savings cycles start in different months (staggered), or all at once? | C11: A loan must end before the CMG's share-out, so a 12-month loan only fits a CMG that borrows at the very start of its cycle. | D11: v0.2
A12: 8 | B12: With the lender discount removed, is the lender's only income the interest margin plus the lender incentives? Does the lender pay anything for the TAMISEMI advance? | C12: Shows whether lending is worth it for the lender. | D12: v0.2
A13: 9 | B13: Should the 15-working-day disbursement rule apply to each new advance across the cycle, not only the first? | C13: Sets how fast money can go out each month. | D13: v0.2
A14: 10 | B14: Are defaulted loans written off at maturity, or chased into the next year (recoveries)? | C14: Recoveries would add money back to the corpus later. | D14: v0.2
A15: 11 | B15: Who should be able to edit the 'PAMOJA Model Inputs' GUI, and does each district need its own editor? | C15: The GUI page is currently shared only with its owner; wider access needs a deliberate share decision. | D15: v0.3
A16: 12 | B16: What should the risk share of defaults between TAMISEMI and the lender actually be, and should it vary by lender or by performance? Should the lender ever keep part of the repaid principal instead of returning all of it to TAMISEMI? | C16: Placeholders now: TAMISEMI absorbs 50% of every default, the lender the other 50%; the lender returns 100% of repaid principal to TAMISEMI. Matches question 12 on the flowchart (trigger and timing of risk share are still open). | D16: v0.4

Sheet Glossary
A1: Glossary
A2: Acronyms and terms used in this model.
A4: Term | B4: Meaning
A5: Advance | B5: Money TAMISEMI sends a lender ahead of lending, based on the CMG pool allocated to that lender.
A6: Allocation | B6: The share of the lending corpus given to a district, based on its loan demand.
A7: Annual cycle | B7: The CMG's savings year. Loans must be repaid before the share-out at the end.
A8: Break-even default rate | B8: The highest default rate the default budget and TAMISEMI's risk share can cover and still restore the corpus.
A9: CMG | B9: Community Microfinance Group: a savings group whose members save and lend to each other.
A10: Corpus | B10: The pool of money available to lend ($24m less the $4m set aside for incentives).
A11: Default | B11: A loan, or part of a loan, that is not repaid.
A12: Default budget / loss reserve | B12: The share of interest set aside to cover TAMISEMI's risk share of defaults.
A13: Demand | B13: Number of CMGs x loan per CMG, before any scaling down.
A14: Flat interest | B14: Interest worked out on the full loan amount for the whole term, not on the falling balance.
A15: Incentive | B15: A payment to reward good results (lenders: lending well; CMGs: on-time repayment).
... A33: TZS / USD | B33: Tanzanian shilling / United States dollar.
