Workbook

Sheet Read me
A1: PAMOJA simplified financial model - v0.5 (draft)
A2: How $24m flows TAMISEMI -> Lenders -> CMGs as loans, and back as repayments.
A5: HOW TO USE
A6: 1. Change the yellow cells with blue numbers only. Everything else is a formula.
A7: 2. Inputs: fund size, lending rules, lending timing and the split of interest.
A8: 3. Districts: CMG numbers, savings and loan size per LGA.
A9: 4. Monthly cycle: when loans go out and come back over 24 months (year 1 lending, year 2 run-off).
A10: 5. Fund flow: totals for all loans made in the year, with a check that the corpus is restored.
A11: 6. Pilot districts / District timeline / Corpus rollout: a separate, weekly view of loan issuance
A12: for 8 pilot districts (see CHANGES IN v0.5 below).
A13: 7. Open questions: things to settle. Glossary: acronyms and terms.
A15: IMPORTANT
... A82: - Exchange rate (TZS / USD) and inflation.

Sheet Inputs
A1: Inputs
A2: Yellow cells are inputs. Dummy values - replace with agreed figures.
A4: Item | B4: Value | C4: Unit | D4: Note
A5: FUND
A6: Total PAMOJA fund | B6: 24000000 | C6: USD | D6: From TAMISEMI
A7: Lender incentives (set aside) | B7: 2000000 | C7: USD | D7: Not lent out
A8: CMG incentives (set aside) | B8: 2000000 | C8: USD | D8: Not lent out
A9: Lending corpus | B9: =B6-B7-B8 | C9: USD | D9: Money available to lend
A10: LENDING RULES
A11: Maximum Loan:Savings ratio | B11: 0.5 | C11: x | D11: Loan must not exceed this x CMG savings
A12: Interest rate (flat, per year) | B12: 0.18 | C12: % | D12: Placeholder; must be at or below TAMISEMI ceiling
A13: Maximum loan tenure | B13: 12 | C13: months | D13: Policy limit
A14: Loan term used in the model | B14: 6 | C14: months | D14: Must be 1 to the maximum tenure
A15: Check: term within maximum | B15: =IF(AND(B14>=1,B14<=B13),"OK","ERROR: term above maximum tenure")
A16: Portfolio default rate (budget) | B16: 0.05 | C16: % | D16: % of principal lent that is not repaid
A17: LENDING TIMING (across the cycle)
A18: Last month lenders can make new loans | B18: 12 | C18: month | D18: 1 to 12. Spread of new loans is set on 'Monthly cycle'
A19: % of principal repaid that is lent out again | B19: 0 | C19: % | D19: 0% = no re-lending (see question 4)
A20: Latest month to lend if all cash must be back by month 12 | B20: =MAX(0,12-B14) | C20: month | D20: 0 means only at the very start of the year
A21: SPLIT OF INTEREST COLLECTED
A22: Default budget (loss reserve) | B22: 0.3 | C22: % | D22: Returned to fund to cover defaults
A23: TAMISEMI share of interest | B23: 0.1 | C23: % | D23: Placeholder
A24: Region service fee | B24: 0.05 | C24: % | D24: Placeholder
A25: LGA service fee | B25: 0.05 | C25: % | D25: Placeholder
A26: Lender margin (remainder) | B26: =1-SUM(B22:B25) | C26: % | D26: What is left for the lender
A27: Check: split adds to 100% or less | B27: =IF(B26>=0,"OK","ERROR: over 100%")
A28: PRINCIPAL SETTLEMENT AND RISK SHARE
A29: TAMISEMI share of repaid principal | B29: 1 | C29: % | D29: Share of every repaid instalment returned to the TAMISEMI corpus
A30: Lender share of repaid principal (remainder) | B30: =1-B29 | C30: % | D30: Kept by the lender; computed from the TAMISEMI share above
A31: TAMISEMI risk share of defaults | B31: 0.5 | C31: % | D31: Share of every default TAMISEMI absorbs against the corpus. Placeholder - see question 12
A32: Lender risk share of defaults (remainder) | B32: =1-B31 | C32: % | D32: The lender's own loss on a default; computed from the TAMISEMI risk share above

Sheet Districts
A1: Allocation by district (LGA)
A2: Dummy data. Add real LGAs in the yellow cells; up to 20 rows. Allocates the first round of lending only.
A4: District (LGA) | B4: Number of CMGs | C4: Average savings per CMG (USD) | D4: Average loan asked per CMG (USD) | E4: Loan cap per CMG = savings x ratio | F4: Loan per CMG (smaller of the two) | G4: Loan:Savings ratio used | H4: Demand (USD) | I4: Allocation (USD) | J4: Share of corpus
A5: District A | B5: 2500 | C5: 4000 | D5: 2500 | E5: =IF(B5="","",C5*Inputs!$B$11) | F5: =IF(B5="","",MIN(D5,E5)) | G5: =IF(B5="","",F5/C5) | H5: =IF(B5="",0,B5*F5) | I5: =IF(B5="",0,H5*$B$28) | J5: =IF(B5="","",I5/Inputs!$B$9)
A6: District B | B6: 1800 | C6: 3000 | D6: 2000 | E6: =IF(B6="","",C6*Inputs!$B$11) | F6: =IF(B6="","",MIN(D6,E6)) | G6: =IF(B6="","",F6/C6) | H6: =IF(B6="",0,B6*F6) | I6: =IF(B6="",0,H6*$B$28) | J6: =IF(B6="","",I6/Inputs!$B$9)
A7: District C | B7: 3200 | C7: 5000 | D7: 3000 | E7: =IF(B7="","",C7*Inputs!$B$11) | F7: =IF(B7="","",MIN(D7,E7)) | G7: =IF(B7="","",F7/C7) | H7: =IF(B7="",0,B7*F7) | I7: =IF(B7="",0,H7*$B$28) | J7: =IF(B7="","",I7/Inputs!$B$9)
A8: District D | B8: 1500 | C8: 3500 | D8: 1500 | E8: =IF(B8="","",C8*Inputs!$B$11) | F8: =IF(B8="","",MIN(D8,E8)) | G8: =IF(B8="","",F8/C8) | H8: =IF(B8="",0,B8*F8) | I8: =IF(B8="",0,H8*$B$28) | J8: =IF(B8="","",I8/Inputs!$B$9)
A9: District E | B9: 2000 | C9: 4500 | D9: 2500 | E9: =IF(B9="","",C9*Inputs!$B$11) | F9: =IF(B9="","",MIN(D9,E9)) | G9: =IF(B9="","",F9/C9) | H9: =IF(B9="",0,B9*F9) | I9: =IF(B9="",0,H9*$B$28) | J9: =IF(B9="","",I9/Inputs!$B$9)
E10: =IF(B10="","",C10*Inputs!$B$11) | F10: =IF(B10="","",MIN(D10,E10)) | G10: =IF(B10="","",F10/C10) | H10: =IF(B10="",0,B10*F10) | I10: =IF(B10="",0,H10*$B$28) | J10: =IF(B10="","",I10/Inputs!$B$9)
E11: =IF(B11="","",C11*Inputs!$B$11) | F11: =IF(B11="","",MIN(D11,E11)) | G11: =IF(B11="","",F11/C11) | H11: =IF(B11="",0,B11*F11) | I11: =IF(B11="",0,H11*$B$28) | J11: =IF(B11="","",I11/Inputs!$B$9)
E12: =IF(B12="","",C12*Inputs!$B$11) | F12: =IF(B12="","",MIN(D12,E12)) | G12: =IF(B12="","",F12/C12) | H12: =IF(B12="",0,B12*F12) | I12: =IF(B12="",0,H12*$B$28) | J12: =IF(B12="","",I12/Inputs!$B$9)
E13: =IF(B13="","",C13*Inputs!$B$11) | F13: =IF(B13="","",MIN(D13,E13)) | G13: =IF(B13="","",F13/C13) | H13: =IF(B13="",0,B13*F13) | I13: =IF(B13="",0,H13*$B$28) | J13: =IF(B13="","",I13/Inputs!$B$9)
E14: =IF(B14="","",C14*Inputs!$B$11) | F14: =IF(B14="","",MIN(D14,E14)) | G14: =IF(B14="","",F14/C14) | H14: =IF(B14="",0,B14*F14) | I14: =IF(B14="",0,H14*$B$28) | J14: =IF(B14="","",I14/Inputs!$B$9)
E15: =IF(B15="","",C15*Inputs!$B$11) | F15: =IF(B15="","",MIN(D15,E15)) | G15: =IF(B15="","",F15/C15) | H15: =IF(B15="",0,B15*F15) | I15: =IF(B15="",0,H15*$B$28) | J15: =IF(B15="","",I15/Inputs!$B$9)
E16: =IF(B16="","",C16*Inputs!$B$11) | F16: =IF(B16="","",MIN(D16,E16)) | G16: =IF(B16="","",F16/C16) | H16: =IF(B16="",0,B16*F16) | I16: =IF(B16="",0,H16*$B$28) | J16: =IF(B16="","",I16/Inputs!$B$9)
E17: =IF(B17="","",C17*Inputs!$B$11) | F17: =IF(B17="","",MIN(D17,E17)) | G17: =IF(B17="","",F17/C17) | H17: =IF(B17="",0,B17*F17) | I17: =IF(B17="",0,H17*$B$28) | J17: =IF(B17="","",I17/Inputs!$B$9)
E18: =IF(B18="","",C18*Inputs!$B$11) | F18: =IF(B18="","",MIN(D18,E18)) | G18: =IF(B18="","",F18/C18) | H18: =IF(B18="",0,B18*F18) | I18: =IF(B18="",0,H18*$B$28) | J18: =IF(B18="","",I18/Inputs!$B$9)
E19: =IF(B19="","",C19*Inputs!$B$11) | F19: =IF(B19="","",MIN(D19,E19)) | G19: =IF(B19="","",F19/C19) | H19: =IF(B19="",0,B19*F19) | I19: =IF(B19="",0,H19*$B$28) | J19: =IF(B19="","",I19/Inputs!$B$9)
E20: =IF(B20="","",C20*Inputs!$B$11) | F20: =IF(B20="","",MIN(D20,E20)) | G20: =IF(B20="","",F20/C20) | H20: =IF(B20="",0,B20*F20) | I20: =IF(B20="",0,H20*$B$28) | J20: =IF(B20="","",I20/Inputs!$B$9)
E21: =IF(B21="","",C21*Inputs!$B$11) | F21: =IF(B21="","",MIN(D21,E21)) | G21: =IF(B21="","",F21/C21) | H21: =IF(B21="",0,B21*F21) | I21: =IF(B21="",0,H21*$B$28) | J21: =IF(B21="","",I21/Inputs!$B$9)
... E24: =IF(B24="","",C24*Inputs!$B$11) | F24: =IF(B24="","",MIN(D24,E24)) | G24: =IF(B24="","",F24/C24) | H24: =IF(B24="",0,B24*F24) | I24: =IF(B24="",0,H24*$B$28) | J24: =IF(B24="","",I24/Inputs!$B$9)
A25: TOTAL | B25: =SUM(B5:B24) | H25: =SUM(H5:H24) | I25: =SUM(I5:I24) | J25: =SUM(J5:J24)
A27: Lending corpus | B27: =Inputs!$B$9
A28: Scale factor (1 = full demand met) | B28: =IF(H25=0,0,MIN(1,B27/H25))
A29: Corpus not used | B29: =B27-I25
A30: Demand not met | B30: =H25-I25

Sheet Fund flow
A1: Fund flow: all loans made in year 1, until they close
A2: TAMISEMI -> Lenders -> CMGs -> back. All formulas; totals come from 'Monthly cycle'.
A4: Step | B4: Amount (USD) | C4: From -> To | D4: How it is worked out
A5: 1. MONEY OUT
A6: Total PAMOJA fund | B6: =Inputs!$B$6 | C6: TAMISEMI
A7: Lender incentives set aside | B7: =Inputs!$B$7 | C7: TAMISEMI -> Lenders | D7: Paid later, not lent
A8: CMG incentives set aside | B8: =Inputs!$B$8 | C8: TAMISEMI -> CMGs | D8: Paid later, not lent
A9: Advances to lenders (new loans from corpus) | B9: ='Monthly cycle'!$Z$8 | C9: TAMISEMI -> Lenders | D9: Sum over the months
A10: Corpus not lent (returned) | B10: =Inputs!$B$9-B9 | C10: Lenders -> TAMISEMI | D10: Unused advance
A11: Repayments lent out again | B11: ='Monthly cycle'!$Z$9 | C11: Lenders -> CMGs | D11: Re-lending
A12: Total loans to CMGs | B12: =B9+B11 | C12: Lenders -> CMGs
A13: 2. MONEY BACK FROM CMGs
A14: Principal defaulted | B14: =B12*Inputs!$B$16 | D14: Loans x default rate
A15: Principal repaid by CMGs (gross) | B15: ='Monthly cycle'!$Z$12 | C15: CMGs -> Lenders | D15: Loans - defaults
A16: TAMISEMI's share of repaid principal | B16: ='Monthly cycle'!$Z$15 | C16: Lenders -> TAMISEMI | D16: Repaid gross x TAMISEMI share of repaid principal
A17: Kept by the lender (repaid principal not returned) | B17: =B15-B16 | C17: Kept by lenders | D17: Repaid gross x lender share
A18: Interest collected | B18: ='Monthly cycle'!$Z$13 | C18: CMGs -> Lenders | D18: Flat: repaid x rate x term/12
A19: Total repayments | B19: =B15+B18 | C19: CMGs -> Lenders
A20: 3. SPLIT OF INTEREST
A21: Default budget (loss reserve) | B21: =B18*Inputs!$B$22 | C21: Lenders -> TAMISEMI
A22: TAMISEMI share of interest | B22: =B18*Inputs!$B$23 | C22: Lenders -> TAMISEMI
A23: Region service fee | B23: =B18*Inputs!$B$24 | C23: -> Region
A24: LGA service fee | B24: =B18*Inputs!$B$25 | C24: -> LGA
A25: Lender margin (from interest) | B25: =B18*Inputs!$B$26 | C25: Kept by lenders | D25: Remainder
A26: 4. RISK SHARE OF DEFAULTS
A27: TAMISEMI's risk share of defaults (absorbed by TAMISEMI) | B27: =B14*Inputs!$B$31 | C27: Loss to TAMISEMI | D27: Defaulted principal x TAMISEMI risk share
A28: Lender's risk share of defaults (the lender's own loss) | B28: =B14*Inputs!$B$32 | C28: Loss to lender | D28: Defaulted principal x lender risk share
A29: Lender's risk-share compensation paid into the fund | B29: ='Monthly cycle'!$Z$16 | C29: Lenders -> TAMISEMI | D29: Should equal the lender's risk share above
A30: Lender's net result (margin - own risk share - principal kept) | B30: =B25-B28+B17 | D30: Whether lending is worth it for the lender
A31: 5. CORPUS CHECK (after all loans close)
A32: Corpus at start | B32: =Inputs!$B$9
A33: Less: TAMISEMI's risk share of defaults | B33: =-B27
A34: Less: repaid principal kept by the lender | B34: =-B17
A35: Plus default budget added back | B35: =B21 | D35: Covers TAMISEMI's risk share of defaults
A36: Corpus at end | B36: =B32+B33+B34+B35
A37: Gap (end - start) | B37: =B36-B32 | D37: Negative = corpus NOT restored
A38: Result | B38: =IF(B37>=-0.5,"Corpus restored","Corpus NOT restored - raise interest share for defaults or rate")
A39: Default budget needed (% of interest) | B39: =IF(B18=0,0,B27/B18) | D39: Minimum share of interest to cover TAMISEMI's risk share of defaults
A40: Break-even default rate | B40: =Inputs!$B$22*Inputs!$B$12*Inputs!$B$14/12/(Inputs!$B$31+Inputs!$B$22*Inputs!$B$12*Inputs!$B$14/12) | D40: Highest default rate the current split and risk share can cover | F40: Chart data (auto - do not edit)
A41: Check: matches month-24 cash on 'Monthly cycle' | B41: =IF(ABS(B36-'Monthly cycle'!Y18)<1,"OK","ERROR") | F41: Money not lent (returned to TAMISEMI) | G41: =B10
...

Sheet Monthly cycle
A1: Monthly cycle (24 months: year 1 lending, year 2 run-off)
A2: Enter the % of the allocated amount lent as NEW loans each month (yellow, months 1-12). Repayments are equal monthly instalments over the loan term.
A4: Line | B4: M1 | C4: M2 | D4: M3 | E4: M4 | F4: M5 | G4: M6 | H4: M7 | I4: M8 | J4: M9 | K4: M10 | L4: M11 | M4: M12 | N4: M13 | O4: M14 | P4: M15 | Q4: M16 | R4: M17 | S4: M18 | T4: M19 | U4: M20 | V4: M21 | W4: M22 | X4: M23 | Y4: M24 | Z4: Total
A5: Month number | B5: 1 | C5: 2 | D5: 3 | E5: 4 | F5: 5 | G5: 6 | H5: 7 | I5: 8 | J5: 9 | K5: 10 | L5: 11 | M5: 12 | N5: 13 | O5: 14 | P5: 15 | Q5: 16 | R5: 17 | S5: 18 | T5: 19 | U5: 20 | V5: 21 | W5: 22 | X5: 23 | Y5: 24
A6: Year | B6: 1 | C6: 1 | D6: 1 | E6: 1 | F6: 1 | G6: 1 | H6: 1 | I6: 1 | J6: 1 | K6: 1 | L6: 1 | M6: 1 | N6: 2 | O6: 2 | P6: 2 | Q6: 2 | R6: 2 | S6: 2 | T6: 2 | U6: 2 | V6: 2 | W6: 2 | X6: 2 | Y6: 2
A7: % of allocation lent as NEW loans this month | B7: 0.25 | C7: 0.2 | D7: 0.15 | E7: 0.1 | F7: 0.1 | G7: 0.1 | H7: 0.05 | I7: 0.05 | J7: 0 | K7: 0 | L7: 0 | M7: 0 | N7: 0 | O7: 0 | P7: 0 | Q7: 0 | R7: 0 | S7: 0 | T7: 0 | U7: 0 | V7: 0 | W7: 0 | X7: 0 | Y7: 0 | Z7: =SUM(B7:M7)
A8: New loans from the corpus | B8: =IF(B$5<=Inputs!$B$18,B7*Districts!$I$25,0) | C8: =IF(C$5<=Inputs!$B$18,C7*Districts!$I$25,0) | D8: =IF(D$5<=Inputs!$B$18,D7*Districts!$I$25,0) | E8: =IF(E$5<=Inputs!$B$18,E7*Districts!$I$25,0) | F8: =IF(F$5<=Inputs!$B$18,F7*Districts!$I$25,0) | G8: =IF(G$5<=Inputs!$B$18,G7*Districts!$I$25,0) | H8: =IF(H$5<=Inputs!$B$18,H7*Districts!$I$25,0) | I8: =IF(I$5<=Inputs!$B$18,I7*Districts!$I$25,0) | ... Y8: =IF(Y$5<=Inputs!$B$18,Y7*Districts!$I$25,0) | Z8: =SUM(B8:Y8)
A9: Re-lent repayments | B9: =0 | C9: =IF(C$5<=Inputs!$B$18,B12*Inputs!$B$19,0) | D9: =IF(D$5<=Inputs!$B$18,C12*Inputs!$B$19,0) | E9: =IF(E$5<=Inputs!$B$18,D12*Inputs!$B$19,0) | F9: =IF(F$5<=Inputs!$B$18,E12*Inputs!$B$19,0) | G9: =IF(G$5<=Inputs!$B$18,F12*Inputs!$B$19,0) | H9: =IF(H$5<=Inputs!$B$18,G12*Inputs!$B$19,0) | I9: =IF(I$5<=Inputs!$B$18,H12*Inputs!$B$19,0) | J9: =IF(J$5<=Inputs!$B$18,I12*Inputs!$B$19,0) | ... Y9: =IF(Y$5<=Inputs!$B$18,X12*Inputs!$B$19,0) | Z9: =SUM(B9:Y9)
A10: Total loans made this month | B10: =B8+B9 | C10: =C8+C9 | D10: =D8+D9 | E10: =E8+E9 | F10: =F8+F9 | G10: =G8+G9 | H10: =H8+H9 | I10: =I8+I9 | ... Y10: =Y8+Y9 | Z10: =SUM(B10:Y10)
A11: Principal due | B11: =0 | C11: =SUMIFS($B10:B10,$B$5:B$5,">="&(C$5-Inputs!$B$14))/Inputs!$B$14 | D11: =SUMIFS($B10:C10,$B$5:C$5,">="&(D$5-Inputs!$B$14))/Inputs!$B$14 | E11: =SUMIFS($B10:D10,$B$5:D$5,">="&(E$5-Inputs!$B$14))/Inputs!$B$14 | F11: =SUMIFS($B10:E10,$B$5:E$5,">="&(F$5-Inputs!$B$14))/Inputs!$B$14 | G11: =SUMIFS($B10:F10,$B$5:F$5,">="&(G$5-Inputs!$B$14))/Inputs!$B$14 | H11: =SUMIFS($B10:G10,$B$5:G$5,">="&(H$5-Inputs!$B$14))/Inputs!$B$14 | I11: =SUMIFS($B10:H10,$B$5:H$5,">="&(I$5-Inputs!$B$14))/Inputs!$B$14 | J11: =SUMIFS($B10:I10,$B$5:I$5,">="&(J$5-Inputs!$B$14))/Inputs!$B$14 | ... Y11: =SUMIFS($B10:X10,$B$5:X$5,">="&(Y$5-Inputs!$B$14))/Inputs!$B$14 | Z11: =SUM(B11:Y11)
A12: Principal repaid by CMGs (gross, after defaults) | B12: =B11*(1-Inputs!$B$16) | C12: =C11*(1-Inputs!$B$16) | D12: =D11*(1-Inputs!$B$16) | E12: =E11*(1-Inputs!$B$16) | F12: =F11*(1-Inputs!$B$16) | G12: =G11*(1-Inputs!$B$16) | H12: =H11*(1-Inputs!$B$16) | I12: =I11*(1-Inputs!$B$16) | ... Y12: =Y11*(1-Inputs!$B$16) | Z12: =SUM(B12:Y12)
A13: Interest collected | B13: =B12*Inputs!$B$12/12*Inputs!$B$14 | C13: =C12*Inputs!$B$12/12*Inputs!$B$14 | D13: =D12*Inputs!$B$12/12*Inputs!$B$14 | E13: =E12*Inputs!$B$12/12*Inputs!$B$14 | F13: =F12*Inputs!$B$12/12*Inputs!$B$14 | G13: =G12*Inputs!$B$12/12*Inputs!$B$14 | H13: =H12*Inputs!$B$12/12*Inputs!$B$14 | I13: =I12*Inputs!$B$12/12*Inputs!$B$14 | ... Y13: =Y12*Inputs!$B$12/12*Inputs!$B$14 | Z13: =SUM(B13:Y13)
A14: Default budget returned to fund | B14: =B13*Inputs!$B$22 | C14: =C13*Inputs!$B$22 | D14: =D13*Inputs!$B$22 | E14: =E13*Inputs!$B$22 | F14: =F13*Inputs!$B$22 | G14: =G13*Inputs!$B$22 | H14: =H13*Inputs!$B$22 | I14: =I13*Inputs!$B$22 | ... Y14: =Y13*Inputs!$B$22 | Z14: =SUM(B14:Y14)
A15: TAMISEMI's share of repaid principal (to fund cash) | B15: =B12*Inputs!$B$29 | C15: =C12*Inputs!$B$29 | D15: =D12*Inputs!$B$29 | E15: =E12*Inputs!$B$29 | F15: =F12*Inputs!$B$29 | G15: =G12*Inputs!$B$29 | H15: =H12*Inputs!$B$29 | I15: =I12*Inputs!$B$29 | ... Y15: =Y12*Inputs!$B$29 | Z15: =SUM(B15:Y15)
A16: Lender's risk-share compensation for defaults (to fund cash) | B16: =(B11-B12)*Inputs!$B$32 | C16: =(C11-C12)*Inputs!$B$32 | D16: =(D11-D12)*Inputs!$B$32 | E16: =(E11-E12)*Inputs!$B$32 | F16: =(F11-F12)*Inputs!$B$32 | G16: =(G11-G12)*Inputs!$B$32 | H16: =(H11-H12)*Inputs!$B$32 | I16: =(I11-I12)*Inputs!$B$32 | ... Y16: =(Y11-Y12)*Inputs!$B$32 | Z16: =SUM(B16:Y16)
A17: Loans outstanding (end of month) | B17: =0+B10-B11 | C17: =B17+C10-C11 | D17: =C17+D10-D11 | E17: =D17+E10-E11 | F17: =E17+F10-F11 | G17: =F17+G10-G11 | H17: =G17+H10-H11 | I17: =H17+I10-I11 | J17: =I17+J10-J11 | ... Y17: =X17+Y10-Y11
A18: Fund cash on hand (end of month) | B18: =Inputs!$B$9-B10+B15+B16+B14 | C18: =B18-C10+C15+C16+C14 | D18: =C18-D10+D15+D16+D14 | E18: =D18-E10+E15+E16+E14 | F18: =E18-F10+F15+F16+F14 | G18: =F18-G10+G15+G16+G14 | H18: =G18-H10+H15+H16+H14 | I18: =H18-I10+I15+I16+I14 | J18: =I18-J10+J15+J16+J14 | ... Y18: =X18-Y10+Y15+Y16+Y14
A19: Cash + loans outstanding | B19: =B18+B17 | C19: =C18+C17 | D19: =D18+D17 | E19: =E18+E17 | F19: =F18+F17 | G19: =G18+G17 | H19: =H18+H17 | I19: =I18+I17 | ... Y19: =Y18+Y17
A20: (helper) month if cash is back to corpus | B20: =IF(B18>=Inputs!$B$9-0.5,B5,999) | C20: =IF(C18>=Inputs!$B$9-0.5,C5,999) | D20: =IF(D18>=Inputs!$B$9-0.5,D5,999) | E20: =IF(E18>=Inputs!$B$9-0.5,E5,999) | F20: =IF(F18>=Inputs!$B$9-0.5,F5,999) | G20: =IF(G18>=Inputs!$B$9-0.5,G5,999) | H20: =IF(H18>=Inputs!$B$9-0.5,H5,999) | I20: =IF(I18>=Inputs!$B$9-0.5,I5,999) | ... Y20: =IF(Y18>=Inputs!$B$9-0.5,Y5,999)
A22: YEAR-END SNAPSHOT (end of month 12)
A23: Fund cash on hand at month 12 | B23: =M18
A24: Money still out on loan at month 12 (repaid in year 2) | B24: =M17
A25: Cash + loans still out | B25: =M19
A26: Share of corpus back as cash at month 12 | B26: =M18/Inputs!$B$9
A27: Total loans made in year 1 (incl. re-lending) | B27: =SUM(B10:M10)
A28: Times the corpus was lent in year 1 (turnover) | B28: =SUM(B10:M10)/Inputs!$B$9
A29: First month the corpus is fully back as cash | B29: =IF(MIN(B20:Y20)=999,"Not within 24 months (defaults not covered)",MIN(B20:Y20))
A30: Fund cash at month 24 (all loans closed) | B30: =Y18
A31: Check: new-loan % adds to 100% | B31: =IF(ABS(Z7-1)<0.0001,"OK","ERROR: adjust row 7")
A32: Check: no new loans after the last lending month | B32: =IF(SUMPRODUCT((B5:M5>Inputs!$B$18)*B7:M7)>0,"WARNING: some % is after the last lending month and is ignored","OK")
A34: Note: fund cash counts TAMISEMI's share of repaid principal, the lender's risk-share compensation for defaults, and the default-budget share of interest. Interest shares also go to TAMISEMI, the region, the LGA and the lender; any repaid principal kept by the lender does not come back to the fund. The thick line marks year end.

Sheet Pilot districts
A1: Pilot districts
A2: 8 districts for the weekly issuance timeline. All data below is placeholder.
A4: Item | B4: Value | C4: Unit | D4: Note
A5: PILOT CORPUS AND SHARED ASSUMPTIONS
A6: Pilot corpus (USD) | B6: 6000000 | C6: USD | D6: A separate, smaller pool from the annual $20m model - not yet reconciled with it (question 13)
A7: Maximum Loan:Savings ratio (from Inputs) | B7: =Inputs!$B$11 | C7: x | D7: Reused from the Inputs sheet
A8: Interest rate (from Inputs) | B8: =Inputs!$B$12 | C8: % | D8: Reused from the Inputs sheet
A9: Portfolio default rate (from Inputs) | B9: =Inputs!$B$16 | C9: % | D9: Reused from the Inputs sheet
A10: Term used in this weekly model | B10: 26 | C10: weeks | D10: Separate from the annual model's monthly term
A11: Appraisal -> disbursal conversion rate | B11: 0.8 | C11: % | D11: Share of appraised CMGs that are approved AND accept the loan
A12: Redeployment mode (District timeline sheet) | B12: 1 | C12: 0/1/2 | D12: 0 = hold repayments as cash, 1 = same FI redeploys them, 2 = handed to a 2nd FI in the district (same maths, different label)
A14: District | B14: Number of CMGs | C14: Avg savings/CMG (USD) | D14: Avg loan ask/CMG (USD) | E14: Loan cap/CMG | F14: Loan/CMG | G14: Demand (USD) | H14: Full allocation (USD) | I14: # FIs assigned | J14: Weekly capacity/FI (CMGs) | K14: Combined weekly capacity | L14: Application -> disbursal lag (wks) | M14: Rollout start week
A15: District 1 | B15: 400 | C15: 4000 | D15: 2500 | E15: =C15*$B$7 | F15: =MIN(D15,E15) | G15: =B15*F15 | H15: =G15*$B$26 | I15: 2 | J15: 6 | K15: =I15*J15 | L15: 2 | M15: 1
A16: District 2 | B16: 350 | C16: 3500 | D16: 2200 | E16: =C16*$B$7 | F16: =MIN(D16,E16) | G16: =B16*F16 | H16: =G16*$B$26 | I16: 2 | J16: 5 | K16: =I16*J16 | L16: 2 | M16: 1
A17: District 3 | B17: 500 | C17: 4500 | D17: 2800 | E17: =C17*$B$7 | F17: =MIN(D17,E17) | G17: =B17*F17 | H17: =G17*$B$26 | I17: 3 | J17: 5 | K17: =I17*J17 | L17: 3 | M17: 3
A18: District 4 | B18: 300 | C18: 3000 | D18: 2000 | E18: =C18*$B$7 | F18: =MIN(D18,E18) | G18: =B18*F18 | H18: =G18*$B$26 | I18: 1 | J18: 6 | K18: =I18*J18 | L18: 2 | M18: 5
A19: District 5 | B19: 450 | C19: 5000 | D19: 3000 | E19: =C19*$B$7 | F19: =MIN(D19,E19) | G19: =B19*F19 | H19: =G19*$B$26 | I19: 2 | J19: 5 | K19: =I19*J19 | L19: 3 | M19: 5
A20: District 6 | B20: 250 | C20: 3500 | D20: 2200 | E20: =C20*$B$7 | F20: =MIN(D20,E20) | G20: =B20*F20 | H20: =G20*$B$26 | I20: 1 | J20: 5 | K20: =I20*J20 | L20: 2 | M20: 9
A21: District 7 | B21: 380 | C21: 4000 | D21: 2500 | E21: =C21*$B$7 | F21: =MIN(D21,E21) | G21: =B21*F21 | H21: =G21*$B$26 | I21: 2 | J21: 4 | K21: =I21*J21 | L21: 3 | M21: 13
A22: District 8 | B22: 320 | C22: 3800 | D22: 2300 | E22: =C22*$B$7 | F22: =MIN(D22,E22) | G22: =B22*F22 | H22: =G22*$B$26 | I22: 1 | J22: 6 | K22: =I22*J22 | L22: 2 | M22: 17
A23: TOTAL | B23: =SUM(B15:B22) | G23: =SUM(G15:G22) | H23: =SUM(H15:H22) | K23: =SUM(K15:K22)
A25: Pilot corpus | B25: =B6
A26: Scale factor (1 = full demand met) | B26: =IF(G23=0,0,MIN(1,B25/G23))
A27: Corpus not used | B27: =B25-H23
A28: Demand not met | B28: =G23-H23

Sheet District timeline
A1: District timeline: weekly loan issuance cascade
A2: Pick a pilot district below. Weeks run down the rows so the cascade charts naturally.
A4: Pick a district: | B4: District 1
A6: Item | B6: Value | C6: Unit | D6: Note
A7: SELECTED DISTRICT'S PARAMETERS (looked up from 'Pilot districts')
A8: Number of CMGs | B8: =INDEX('Pilot districts'!$B$15:$B$22,MATCH($B$4,'Pilot districts'!$A$15:$A$22,0)) | C8: CMGs
A9: Loan per CMG (USD) | B9: =INDEX('Pilot districts'!$F$15:$F$22,MATCH($B$4,'Pilot districts'!$A$15:$A$22,0)) | C9: USD
A10: Full allocation (USD) | B10: =INDEX('Pilot districts'!$H$15:$H$22,MATCH($B$4,'Pilot districts'!$A$15:$A$22,0)) | C10: USD
A11: Combined weekly appraisal capacity | B11: =INDEX('Pilot districts'!$K$15:$K$22,MATCH($B$4,'Pilot districts'!$A$15:$A$22,0)) | C11: CMGs/wk
A12: Application -> disbursal lag | B12: =INDEX('Pilot districts'!$L$15:$L$22,MATCH($B$4,'Pilot districts'!$A$15:$A$22,0)) | C12: weeks
A13: Term used in this weekly model | B13: ='Pilot districts'!B10 | C13: weeks | D13: From 'Pilot districts'
A14: Interest rate | B14: ='Pilot districts'!B8 | C14: % | D14: From 'Pilot districts'
A15: Portfolio default rate | B15: ='Pilot districts'!B9 | C15: % | D15: From 'Pilot districts'
A16: Appraisal -> disbursal conversion rate | B16: ='Pilot districts'!B11 | C16: % | D16: From 'Pilot districts'
A17: Redeployment mode (0/1/2) | B17: ='Pilot districts'!B12 | D17: 0 = hold cash, 1 = same FI redeploys, 2 = 2nd FI in district (same maths)
A19: Week | B19: New CMGs appraised | C19: New CMGs disbursed | D19: Capital disbursed this wk | E19: Cumulative capital disbursed | F19: Capital remaining in pool | G19: Principal due | H19: Principal repaid | I19: Interest collected | J19: Recycled capital | K19: Portfolio Outstanding | L19: Pool exhausted?
A20: 1 | B20: =MAX(0,MIN($B$11,$B$8-0)) | C20: =MIN(IF(A20<=$B$12,0,N(OFFSET(B20,-$B$12,0))*$B$16),IF($B$9=0,0,$B$10/$B$9)) | D20: =C20*$B$9 | E20: =D20 | F20: =$B$10-E20+SUM($J$20:J20) | G20: =0 | H20: =G20*(1-$B$15) | I20: =H20*$B$14/52*$B$13 | J20: =IF($B$17>0,H20,0) | K20: =E20-SUM($H$20:H20) | L20: =IF(F20<$B$9,"Yes","No")
A21: 2 | B21: =MAX(0,MIN($B$11,$B$8-SUM($B$20:B20))) | C21: =MIN(IF(A21<=$B$12,0,N(OFFSET(B21,-$B$12,0))*$B$16),IF($B$9=0,0,F20/$B$9)) | D21: =C21*$B$9 | E21: =E20+D21 | F21: =$B$10-E21+SUM($J$20:J21) | G21: =SUMIFS($D$20:D20,$A$20:A20,">="&(A21-$B$13))/$B$13 | H21: =G21*(1-$B$15) | I21: =H21*$B$14/52*$B$13 | J21: =IF($B$17>0,H21,0) | K21: =E21-SUM($H$20:H21) | L21: =IF(F21<$B$9,"Yes","No")
A22: 3 | B22: =MAX(0,MIN($B$11,$B$8-SUM($B$20:B21))) | C22: =MIN(IF(A22<=$B$12,0,N(OFFSET(B22,-$B$12,0))*$B$16),IF($B$9=0,0,F21/$B$9)) | D22: =C22*$B$9 | E22: =E21+D22 | F22: =$B$10-E22+SUM($J$20:J22) | G22: =SUMIFS($D$20:D21,$A$20:A21,">="&(A22-$B$13))/$B$13 | H22: =G22*(1-$B$15) | I22: =H22*$B$14/52*$B$13 | J22: =IF($B$17>0,H22,0) | K22: =E22-SUM($H$20:H22) | L22: =IF(F22<$B$9,"Yes","No")
A23: 4 | B23: =MAX(0,MIN($B$11,$B$8-SUM($B$20:B22))) | C23: =MIN(IF(A23<=$B$12,0,N(OFFSET(B23,-$B$12,0))*$B$16),IF($B$9=0,0,F22/$B$9)) | D23: =C23*$B$9 | E23: =E22+D23 | F23: =$B$10-E23+SUM($J$20:J23) | G23: =SUMIFS($D$20:D22,$A$20:A22,">="&(A23-$B$13))/$B$13 | H23: =G23*(1-$B$15) | I23: =H23*$B$14/52*$B$13 | J23: =IF($B$17>0,H23,0) | K23: =E23-SUM($H$20:H23) | L23: =IF(F23<$B$9,"Yes","No")
A24: 5 | B24: =MAX(0,MIN($B$11,$B$8-SUM($B$20:B23))) | C24: =MIN(IF(A24<=$B$12,0,N(OFFSET(B24,-$B$12,0))*$B$16),IF($B$9=0,0,F23/$B$9)) | D24: =C24*$B$9 | E24: =E23+D24 | F24: =$B$10-E24+SUM($J$20:J24) | G24: =SUMIFS($D$20:D23,$A$20:A23,">="&(A24-$B$13))/$B$13 | H24: =G24*(1-$B$15) | I24: =H24*$B$14/52*$B$13 | J24: =IF($B$17>0,H24,0) | K24: =E24-SUM($H$20:H24) | L24: =IF(F24<$B$9,"Yes","No")
A25: 6 | B25: =MAX(0,MIN($B$11,$B$8-SUM($B$20:B24))) | C25: =MIN(IF(A25<=$B$12,0,N(OFFSET(B25,-$B$12,0))*$B$16),IF($B$9=0,0,F24/$B$9)) | D25: =C25*$B$9 | E25: =E24+D25 | F25: =$B$10-E25+SUM($J$20:J25) | G25: =SUMIFS($D$20:D24,$A$20:A24,">="&(A25-$B$13))/$B$13 | H25: =G25*(1-$B$15) | I25: =H25*$B$14/52*$B$13 | J25: =IF($B$17>0,H25,0) | K25: =E25-SUM($H$20:H25) | L25: =IF(F25<$B$9,"Yes","No")
A26: 7 | B26: =MAX(0,MIN($B$11,$B$8-SUM($B$20:B25))) | C26: =MIN(IF(A26<=$B$12,0,N(OFFSET(B26,-$B$12,0))*$B$16),IF($B$9=0,0,F25/$B$9)) | D26: =C26*$B$9 | E26: =E25+D26 | F26: =$B$10-E26+SUM($J$20:J26) | G26: =SUMIFS($D$20:D25,$A$20:A25,">="&(A26-$B$13))/$B$13 | H26: =G26*(1-$B$15) | I26: =H26*$B$14/52*$B$13 | J26: =IF($B$17>0,H26,0) | K26: =E26-SUM($H$20:H26) | L26: =IF(F26<$B$9,"Yes","No")
A27: 8 | B27: =MAX(0,MIN($B$11,$B$8-SUM($B$20:B26))) | C27: =MIN(IF(A27<=$B$12,0,N(OFFSET(B27,-$B$12,0))*$B$16),IF($B$9=0,0,F26/$B$9)) | D27: =C27*$B$9 | E27: =E26+D27 | F27: =$B$10-E27+SUM($J$20:J27) | G27: =SUMIFS($D$20:D26,$A$20:A26,">="&(A27-$B$13))/$B$13 | H27: =G27*(1-$B$15) | I27: =H27*$B$14/52*$B$13 | J27: =IF($B$17>0,H27,0) | K27: =E27-SUM($H$20:H27) | L27: =IF(F27<$B$9,"Yes","No")
A28: 9 | B28: =MAX(0,MIN($B$11,$B$8-SUM($B$20:B27))) | C28: =MIN(IF(A28<=$B$12,0,N(OFFSET(B28,-$B$12,0))*$B$16),IF($B$9=0,0,F27/$B$9)) | D28: =C28*$B$9 | E28: =E27+D28 | F28: =$B$10-E28+SUM($J$20:J28) | G28: =SUMIFS($D$20:D27,$A$20:A27,">="&(A28-$B$13))/$B$13 | H28: =G28*(1-$B$15) | I28: =H28*$B$14/52*$B$13 | J28: =IF($B$17>0,H28,0) | K28: =E28-SUM($H$20:H28) | L28: =IF(F28<$B$9,"Yes","No")
A29: 10 | B29: =MAX(0,MIN($B$11,$B$8-SUM($B$20:B28))) | C29: =MIN(IF(A29<=$B$12,0,N(OFFSET(B29,-$B$12,0))*$B$16),IF($B$9=0,0,F28/$B$9)) | D29: =C29*$B$9 | E29: =E28+D29 | F29: =$B$10-E29+SUM($J$20:J29) | G29: =SUMIFS($D$20:D28,$A$20:A28,">="&(A29-$B$13))/$B$13 | H29: =G29*(1-$B$15) | I29: =H29*$B$14/52*$B$13 | J29: =IF($B$17>0,H29,0) | K29: =E29-SUM($H$20:H29) | L29: =IF(F29<$B$9,"Yes","No")
A30: 11 | B30: =MAX(0,MIN($B$11,$B$8-SUM($B$20:B29))) | C30: =MIN(IF(A30<=$B$12,0,N(OFFSET(B30,-$B$12,0))*$B$16),IF($B$9=0,0,F29/$B$9)) | D30: =C30*$B$9 | E30: =E29+D30 | F30: =$B$10-E30+SUM($J$20:J30) | G30: =SUMIFS($D$20:D29,$A$20:A29,">="&(A30-$B$13))/$B$13 | H30: =G30*(1-$B$15) | I30: =H30*$B$14/52*$B$13 | J30: =IF($B$17>0,H30,0) | K30: =E30-SUM($H$20:H30) | L30: =IF(F30<$B$9,"Yes","No")
A31: 12 | B31: =MAX(0,MIN($B$11,$B$8-SUM($B$20:B30))) | C31: =MIN(IF(A31<=$B$12,0,N(OFFSET(B31,-$B$12,0))*$B$16),IF($B$9=0,0,F30/$B$9)) | D31: =C31*$B$9 | E31: =E30+D31 | F31: =$B$10-E31+SUM($J$20:J31) | G31: =SUMIFS($D$20:D30,$A$20:A30,">="&(A31-$B$13))/$B$13 | H31: =G31*(1-$B$15) | I31: =H31*$B$14/52*$B$13 | J31: =IF($B$17>0,H31,0) | K31: =E31-SUM($H$20:H31) | L31: =IF(F31<$B$9,"Yes","No")
A32: 13 | B32: =MAX(0,MIN($B$11,$B$8-SUM($B$20:B31))) | C32: =MIN(IF(A32<=$B$12,0,N(OFFSET(B32,-$B$12,0))*$B$16),IF($B$9=0,0,F31/$B$9)) | D32: =C32*$B$9 | E32: =E31+D32 | F32: =$B$10-E32+SUM($J$20:J32) | G32: =SUMIFS($D$20:D31,$A$20:A31,">="&(A32-$B$13))/$B$13 | H32: =G32*(1-$B$15) | I32: =H32*$B$14/52*$B$13 | J32: =IF($B$17>0,H32,0) | K32: =E32-SUM($H$20:H32) | L32: =IF(F32<$B$9,"Yes","No")
... A123: 104 | B123: =MAX(0,MIN($B$11,$B$8-SUM($B$20:B122))) | C123: =MIN(IF(A123<=$B$12,0,N(OFFSET(B123,-$B$12,0))*$B$16),IF($B$9=0,0,F122/$B$9)) | D123: =C123*$B$9 | E123: =E122+D123 | F123: =$B$10-E123+SUM($J$20:J123) | G123: =SUMIFS($D$20:D122,$A$20:A122,">="&(A123-$B$13))/$B$13 | H123: =G123*(1-$B$15) | I123: =H123*$B$14/52*$B$13 | J123: =IF($B$17>0,H123,0) | K123: =E123-SUM($H$20:H123) | L123: =IF(F123<$B$9,"Yes","No")
A124: SUMMARY
A125: Weeks to exhaust the pool | B125: =IFERROR(INDEX($A$20:$A$123,MATCH("Yes",$L$20:$L$123,0)),"Not within 104 weeks")
A126: Peak Portfolio Outstanding | B126: =MAX($K$20:$K$123)
A127: Week of peak Portfolio Outstanding | B127: =INDEX($A$20:$A$123,MATCH(MAX($K$20:$K$123),$K$20:$K$123,0))
A128: Total CMGs served | B128: =SUM($C$20:C$123)
A129: Total capital disbursed | B129: =E123
A130: Total capital recycled | B130: =SUM($J$20:J123)
A132: To compare with vs without recycling: change the Redeployment mode on 'Pilot districts' (0 = off) and re-check 'Weeks to exhaust the pool' and 'Total capital disbursed' above.

Sheet Corpus rollout
A1: Corpus rollout: full allocation upfront vs staggered tranches
A2: All 8 pilot districts side by side. Does spending most of the pool on early districts strand later ones?
A4: Item | B4: Value | C4: Unit | D4: Note
A5: ROLLOUT ASSUMPTIONS
A6: Tranche advanced to each district upfront (rest held as TAMISEMI reserve) | B6: 0.7 | C6: % | D6: 100% = the whole allocation goes out on day one, like the annual model
A7: New region funding need (illustrative) | B7: 1500000 | C7: USD | D7: Just to test whether the reserve would cover a call for funds from elsewhere
A9: District | B9: Full allocation (USD) | C9: Committed tranche (USD) | D9: Reserve contribution (USD) | E9: Rollout start week | F9: Combined weekly capacity | G9: Loan/CMG (USD) | H9: Weeks to exhaust tranche
A10: ='Pilot districts'!A15 | B10: ='Pilot districts'!H15 | C10: =B10*$B$6 | D10: =B10-C10 | E10: ='Pilot districts'!M15 | F10: ='Pilot districts'!K15 | G10: ='Pilot districts'!F15 | H10: =IF(F10*G10=0,0,ROUNDUP(C10/(F10*G10),0))
A11: ='Pilot districts'!A16 | B11: ='Pilot districts'!H16 | C11: =B11*$B$6 | D11: =B11-C11 | E11: ='Pilot districts'!M16 | F11: ='Pilot districts'!K16 | G11: ='Pilot districts'!F16 | H11: =IF(F11*G11=0,0,ROUNDUP(C11/(F11*G11),0))
A12: ='Pilot districts'!A17 | B12: ='Pilot districts'!H17 | C12: =B12*$B$6 | D12: =B12-C12 | E12: ='Pilot districts'!M17 | F12: ='Pilot districts'!K17 | G12: ='Pilot districts'!F17 | H12: =IF(F12*G12=0,0,ROUNDUP(C12/(F12*G12),0))
A13: ='Pilot districts'!A18 | B13: ='Pilot districts'!H18 | C13: =B13*$B$6 | D13: =B13-C13 | E13: ='Pilot districts'!M18 | F13: ='Pilot districts'!K18 | G13: ='Pilot districts'!F18 | H13: =IF(F13*G13=0,0,ROUNDUP(C13/(F13*G13),0))
A14: ='Pilot districts'!A19 | B14: ='Pilot districts'!H19 | C14: =B14*$B$6 | D14: =B14-C14 | E14: ='Pilot districts'!M19 | F14: ='Pilot districts'!K19 | G14: ='Pilot districts'!F19 | H14: =IF(F14*G14=0,0,ROUNDUP(C14/(F14*G14),0))
A15: ='Pilot districts'!A20 | B15: ='Pilot districts'!H20 | C15: =B15*$B$6 | D15: =B15-C15 | E15: ='Pilot districts'!M20 | F15: ='Pilot districts'!K20 | G15: ='Pilot districts'!F20 | H15: =IF(F15*G15=0,0,ROUNDUP(C15/(F15*G15),0))
A16: ='Pilot districts'!A21 | B16: ='Pilot districts'!H21 | C16: =B16*$B$6 | D16: =B16-C16 | E16: ='Pilot districts'!M21 | F16: ='Pilot districts'!K21 | G16: ='Pilot districts'!F21 | H16: =IF(F16*G16=0,0,ROUNDUP(C16/(F16*G16),0))
A17: ='Pilot districts'!A22 | B17: ='Pilot districts'!H22 | C17: =B17*$B$6 | D17: =B17-C17 | E17: ='Pilot districts'!M22 | F17: ='Pilot districts'!K22 | G17: ='Pilot districts'!F22 | H17: =IF(F17*G17=0,0,ROUNDUP(C17/(F17*G17),0))
A18: TOTAL | B18: =SUM(B10:B17) | C18: =SUM(C10:C17) | D18: =SUM(D10:D17)
A20: Reserve covers the new region funding need? | B20: =IF(D18>=B7,"Yes","No")
A21: WEEKLY CASCADE - capital disbursed to CMGs, by district (capacity-limited, no recycling)
A22: Week | B22: =A10 | C22: =A11 | D22: =A12 | E22: =A13 | F22: =A14 | G22: =A15 | H22: =A16 | I22: =A17 | J22: Total disbursed | K22: Idle cash at TAMISEMI
A23: 1 | B23: =IF(A23<$E$10,0,MIN($C$10,($F$10*$G$10)*(A23-$E$10+1))) | C23: =IF(A23<$E$11,0,MIN($C$11,($F$11*$G$11)*(A23-$E$11+1))) | D23: =IF(A23<$E$12,0,MIN($C$12,($F$12*$G$12)*(A23-$E$12+1))) | E23: =IF(A23<$E$13,0,MIN($C$13,($F$13*$G$13)*(A23-$E$13+1))) | F23: =IF(A23<$E$14,0,MIN($C$14,($F$14*$G$14)*(A23-$E$14+1))) | G23: =IF(A23<$E$15,0,MIN($C$15,($F$15*$G$15)*(A23-$E$15+1))) | H23: =IF(A23<$E$16,0,MIN($C$16,($F$16*$G$16)*(A23-$E$16+1))) | I23: =IF(A23<$E$17,0,MIN($C$17,($F$17*$G$17)*(A23-$E$17+1))) | J23: =SUM(B23:I23) | K23: ='Pilot districts'!$B$6-SUMPRODUCT(($E$10:$E$17<=A23)*$C$10:$C$17)
A24: 2 | B24: =IF(A24<$E$10,0,MIN($C$10,($F$10*$G$10)*(A24-$E$10+1))) | C24: =IF(A24<$E$11,0,MIN($C$11,($F$11*$G$11)*(A24-$E$11+1))) | D24: =IF(A24<$E$12,0,MIN($C$12,($F$12*$G$12)*(A24-$E$12+1))) | E24: =IF(A24<$E$13,0,MIN($C$13,($F$13*$G$13)*(A24-$E$13+1))) | F24: =IF(A24<$E$14,0,MIN($C$14,($F$14*$G$14)*(A24-$E$14+1))) | G24: =IF(A24<$E$15,0,MIN($C$15,($F$15*$G$15)*(A24-$E$15+1))) | H24: =IF(A24<$E$16,0,MIN($C$16,($F$16*$G$16)*(A24-$E$16+1))) | I24: =IF(A24<$E$17,0,MIN($C$17,($F$17*$G$17)*(A24-$E$17+1))) | J24: =SUM(B24:I24) | K24: ='Pilot districts'!$B$6-SUMPRODUCT(($E$10:$E$17<=A24)*$C$10:$C$17)
A25: 3 | B25: =IF(A25<$E$10,0,MIN($C$10,($F$10*$G$10)*(A25-$E$10+1))) | C25: =IF(A25<$E$11,0,MIN($C$11,($F$11*$G$11)*(A25-$E$11+1))) | D25: =IF(A25<$E$12,0,MIN($C$12,($F$12*$G$12)*(A25-$E$12+1))) | E25: =IF(A25<$E$13,0,MIN($C$13,($F$13*$G$13)*(A25-$E$13+1))) | F25: =IF(A25<$E$14,0,MIN($C$14,($F$14*$G$14)*(A25-$E$14+1))) | G25: =IF(A25<$E$15,0,MIN($C$15,($F$15*$G$15)*(A25-$E$15+1))) | H25: =IF(A25<$E$16,0,MIN($C$16,($F$16*$G$16)*(A25-$E$16+1))) | I25: =IF(A25<$E$17,0,MIN($C$17,($F$17*$G$17)*(A25-$E$17+1))) | J25: =SUM(B25:I25) | K25: ='Pilot districts'!$B$6-SUMPRODUCT(($E$10:$E$17<=A25)*$C$10:$C$17)
A26: 4 | B26: =IF(A26<$E$10,0,MIN($C$10,($F$10*$G$10)*(A26-$E$10+1))) | C26: =IF(A26<$E$11,0,MIN($C$11,($F$11*$G$11)*(A26-$E$11+1))) | D26: =IF(A26<$E$12,0,MIN($C$12,($F$12*$G$12)*(A26-$E$12+1))) | E26: =IF(A26<$E$13,0,MIN($C$13,($F$13*$G$13)*(A26-$E$13+1))) | F26: =IF(A26<$E$14,0,MIN($C$14,($F$14*$G$14)*(A26-$E$14+1))) | G26: =IF(A26<$E$15,0,MIN($C$15,($F$15*$G$15)*(A26-$E$15+1))) | H26: =IF(A26<$E$16,0,MIN($C$16,($F$16*$G$16)*(A26-$E$16+1))) | I26: =IF(A26<$E$17,0,MIN($C$17,($F$17*$G$17)*(A26-$E$17+1))) | J26: =SUM(B26:I26) | K26: ='Pilot districts'!$B$6-SUMPRODUCT(($E$10:$E$17<=A26)*$C$10:$C$17)
A27: 5 | B27: =IF(A27<$E$10,0,MIN($C$10,($F$10*$G$10)*(A27-$E$10+1))) | C27: =IF(A27<$E$11,0,MIN($C$11,($F$11*$G$11)*(A27-$E$11+1))) | D27: =IF(A27<$E$12,0,MIN($C$12,($F$12*$G$12)*(A27-$E$12+1))) | E27: =IF(A27<$E$13,0,MIN($C$13,($F$13*$G$13)*(A27-$E$13+1))) | F27: =IF(A27<$E$14,0,MIN($C$14,($F$14*$G$14)*(A27-$E$14+1))) | G27: =IF(A27<$E$15,0,MIN($C$15,($F$15*$G$15)*(A27-$E$15+1))) | H27: =IF(A27<$E$16,0,MIN($C$16,($F$16*$G$16)*(A27-$E$16+1))) | I27: =IF(A27<$E$17,0,MIN($C$17,($F$17*$G$17)*(A27-$E$17+1))) | J27: =SUM(B27:I27) | K27: ='Pilot districts'!$B$6-SUMPRODUCT(($E$10:$E$17<=A27)*$C$10:$C$17)
A28: 6 | B28: =IF(A28<$E$10,0,MIN($C$10,($F$10*$G$10)*(A28-$E$10+1))) | C28: =IF(A28<$E$11,0,MIN($C$11,($F$11*$G$11)*(A28-$E$11+1))) | D28: =IF(A28<$E$12,0,MIN($C$12,($F$12*$G$12)*(A28-$E$12+1))) | E28: =IF(A28<$E$13,0,MIN($C$13,($F$13*$G$13)*(A28-$E$13+1))) | F28: =IF(A28<$E$14,0,MIN($C$14,($F$14*$G$14)*(A28-$E$14+1))) | G28: =IF(A28<$E$15,0,MIN($C$15,($F$15*$G$15)*(A28-$E$15+1))) | H28: =IF(A28<$E$16,0,MIN($C$16,($F$16*$G$16)*(A28-$E$16+1))) | I28: =IF(A28<$E$17,0,MIN($C$17,($F$17*$G$17)*(A28-$E$17+1))) | J28: =SUM(B28:I28) | K28: ='Pilot districts'!$B$6-SUMPRODUCT(($E$10:$E$17<=A28)*$C$10:$C$17)
A29: 7 | B29: =IF(A29<$E$10,0,MIN($C$10,($F$10*$G$10)*(A29-$E$10+1))) | C29: =IF(A29<$E$11,0,MIN($C$11,($F$11*$G$11)*(A29-$E$11+1))) | D29: =IF(A29<$E$12,0,MIN($C$12,($F$12*$G$12)*(A29-$E$12+1))) | E29: =IF(A29<$E$13,0,MIN($C$13,($F$13*$G$13)*(A29-$E$13+1))) | F29: =IF(A29<$E$14,0,MIN($C$14,($F$14*$G$14)*(A29-$E$14+1))) | G29: =IF(A29<$E$15,0,MIN($C$15,($F$15*$G$15)*(A29-$E$15+1))) | H29: =IF(A29<$E$16,0,MIN($C$16,($F$16*$G$16)*(A29-$E$16+1))) | I29: =IF(A29<$E$17,0,MIN($C$17,($F$17*$G$17)*(A29-$E$17+1))) | J29: =SUM(B29:I29) | K29: ='Pilot districts'!$B$6-SUMPRODUCT(($E$10:$E$17<=A29)*$C$10:$C$17)
A30: 8 | B30: =IF(A30<$E$10,0,MIN($C$10,($F$10*$G$10)*(A30-$E$10+1))) | C30: =IF(A30<$E$11,0,MIN($C$11,($F$11*$G$11)*(A30-$E$11+1))) | D30: =IF(A30<$E$12,0,MIN($C$12,($F$12*$G$12)*(A30-$E$12+1))) | E30: =IF(A30<$E$13,0,MIN($C$13,($F$13*$G$13)*(A30-$E$13+1))) | F30: =IF(A30<$E$14,0,MIN($C$14,($F$14*$G$14)*(A30-$E$14+1))) | G30: =IF(A30<$E$15,0,MIN($C$15,($F$15*$G$15)*(A30-$E$15+1))) | H30: =IF(A30<$E$16,0,MIN($C$16,($F$16*$G$16)*(A30-$E$16+1))) | I30: =IF(A30<$E$17,0,MIN($C$17,($F$17*$G$17)*(A30-$E$17+1))) | J30: =SUM(B30:I30) | K30: ='Pilot districts'!$B$6-SUMPRODUCT(($E$10:$E$17<=A30)*$C$10:$C$17)
A31: 9 | B31: =IF(A31<$E$10,0,MIN($C$10,($F$10*$G$10)*(A31-$E$10+1))) | C31: =IF(A31<$E$11,0,MIN($C$11,($F$11*$G$11)*(A31-$E$11+1))) | D31: =IF(A31<$E$12,0,MIN($C$12,($F$12*$G$12)*(A31-$E$12+1))) | E31: =IF(A31<$E$13,0,MIN($C$13,($F$13*$G$13)*(A31-$E$13+1))) | F31: =IF(A31<$E$14,0,MIN($C$14,($F$14*$G$14)*(A31-$E$14+1))) | G31: =IF(A31<$E$15,0,MIN($C$15,($F$15*$G$15)*(A31-$E$15+1))) | H31: =IF(A31<$E$16,0,MIN($C$16,($F$16*$G$16)*(A31-$E$16+1))) | I31: =IF(A31<$E$17,0,MIN($C$17,($F$17*$G$17)*(A31-$E$17+1))) | J31: =SUM(B31:I31) | K31: ='Pilot districts'!$B$6-SUMPRODUCT(($E$10:$E$17<=A31)*$C$10:$C$17)
A32: 10 | B32: =IF(A32<$E$10,0,MIN($C$10,($F$10*$G$10)*(A32-$E$10+1))) | C32: =IF(A32<$E$11,0,MIN($C$11,($F$11*$G$11)*(A32-$E$11+1))) | D32: =IF(A32<$E$12,0,MIN($C$12,($F$12*$G$12)*(A32-$E$12+1))) | E32: =IF(A32<$E$13,0,MIN($C$13,($F$13*$G$13)*(A32-$E$13+1))) | F32: =IF(A32<$E$14,0,MIN($C$14,($F$14*$G$14)*(A32-$E$14+1))) | G32: =IF(A32<$E$15,0,MIN($C$15,($F$15*$G$15)*(A32-$E$15+1))) | H32: =IF(A32<$E$16,0,MIN($C$16,($F$16*$G$16)*(A32-$E$16+1))) | I32: =IF(A32<$E$17,0,MIN($C$17,($F$17*$G$17)*(A32-$E$17+1))) | J32: =SUM(B32:I32) | K32: ='Pilot districts'!$B$6-SUMPRODUCT(($E$10:$E$17<=A32)*$C$10:$C$17)
A33: 11 | B33: =IF(A33<$E$10,0,MIN($C$10,($F$10*$G$10)*(A33-$E$10+1))) | C33: =IF(A33<$E$11,0,MIN($C$11,($F$11*$G$11)*(A33-$E$11+1))) | D33: =IF(A33<$E$12,0,MIN($C$12,($F$12*$G$12)*(A33-$E$12+1))) | E33: =IF(A33<$E$13,0,MIN($C$13,($F$13*$G$13)*(A33-$E$13+1))) | F33: =IF(A33<$E$14,0,MIN($C$14,($F$14*$G$14)*(A33-$E$14+1))) | G33: =IF(A33<$E$15,0,MIN($C$15,($F$15*$G$15)*(A33-$E$15+1))) | H33: =IF(A33<$E$16,0,MIN($C$16,($F$16*$G$16)*(A33-$E$16+1))) | I33: =IF(A33<$E$17,0,MIN($C$17,($F$17*$G$17)*(A33-$E$17+1))) | J33: =SUM(B33:I33) | K33: ='Pilot districts'!$B$6-SUMPRODUCT(($E$10:$E$17<=A33)*$C$10:$C$17)
A34: 12 | B34: =IF(A34<$E$10,0,MIN($C$10,($F$10*$G$10)*(A34-$E$10+1))) | C34: =IF(A34<$E$11,0,MIN($C$11,($F$11*$G$11)*(A34-$E$11+1))) | D34: =IF(A34<$E$12,0,MIN($C$12,($F$12*$G$12)*(A34-$E$12+1))) | E34: =IF(A34<$E$13,0,MIN($C$13,($F$13*$G$13)*(A34-$E$13+1))) | F34: =IF(A34<$E$14,0,MIN($C$14,($F$14*$G$14)*(A34-$E$14+1))) | G34: =IF(A34<$E$15,0,MIN($C$15,($F$15*$G$15)*(A34-$E$15+1))) | H34: =IF(A34<$E$16,0,MIN($C$16,($F$16*$G$16)*(A34-$E$16+1))) | I34: =IF(A34<$E$17,0,MIN($C$17,($F$17*$G$17)*(A34-$E$17+1))) | J34: =SUM(B34:I34) | K34: ='Pilot districts'!$B$6-SUMPRODUCT(($E$10:$E$17<=A34)*$C$10:$C$17)
... A126: 104 | B126: =IF(A126<$E$10,0,MIN($C$10,($F$10*$G$10)*(A126-$E$10+1))) | C126: =IF(A126<$E$11,0,MIN($C$11,($F$11*$G$11)*(A126-$E$11+1))) | D126: =IF(A126<$E$12,0,MIN($C$12,($F$12*$G$12)*(A126-$E$12+1))) | E126: =IF(A126<$E$13,0,MIN($C$13,($F$13*$G$13)*(A126-$E$13+1))) | F126: =IF(A126<$E$14,0,MIN($C$14,($F$14*$G$14)*(A126-$E$14+1))) | G126: =IF(A126<$E$15,0,MIN($C$15,($F$15*$G$15)*(A126-$E$15+1))) | H126: =IF(A126<$E$16,0,MIN($C$16,($F$16*$G$16)*(A126-$E$16+1))) | I126: =IF(A126<$E$17,0,MIN($C$17,($F$17*$G$17)*(A126-$E$17+1))) | J126: =SUM(B126:I126) | K126: ='Pilot districts'!$B$6-SUMPRODUCT(($E$10:$E$17<=A126)*$C$10:$C$17)

Sheet Open questions
A1: Open questions
A2: To settle before the model uses real figures.
A4: # | B4: Question | C4: Why it matters | D4: Added in | E4: Answer
A5: 1 | B5: Is the Loan:Savings cap on the loan itself (loan must not exceed 0.5 x the CMG's savings)? | C5: Sets the loan cap per CMG on the Districts sheet. | D5: v0.1
A6: 2 | B6: Is interest flat or on the reducing balance? What is TAMISEMI's interest ceiling? | C6: Drives all interest income, and so the default budget. | D6: v0.1
A7: 3 | B7: Are the TAMISEMI, region and LGA amounts a % of interest, or a % of the loan amount? | C7: Changes how much interest is left for the default budget and the lender. | D7: v0.1
A8: 4 | B8: Can repayments be lent out again in the same year? If yes, to whom: new CMGs or second loans to the same CMGs? | C8: Re-lending raises total lending but ties money up longer; the Districts sheet only allocates the first round. | D8: v0.1
A9: 5 | B9: Are the $2m lender and $2m CMG incentive pots paid in full each year, or spread over several years? | C9: Decides whether the corpus stays at $20m every year. | D9: v0.1
A10: 6 | B10: When does TAMISEMI's annual cycle end (e.g. financial year July-June)? At that date, must the corpus be back as CASH, or can loans still running count? | C10: With lending across the cycle and tenures up to 12 months, some money is always out on loan at year end. | D10: v0.2
A11: 7 | B11: Do CMG savings cycles start in different months (staggered), or all at once? | C11: A loan must end before the CMG's share-out, so a 12-month loan only fits a CMG that borrows at the very start of its cycle. | D11: v0.2
A12: 8 | B12: With the lender discount removed, is the lender's only income the interest margin plus the lender incentives? Does the lender pay anything for the TAMISEMI advance? | C12: Shows whether lending is worth it for the lender. | D12: v0.2
A13: 9 | B13: Should the 15-working-day disbursement rule apply to each new advance across the cycle, not only the first? | C13: Sets how fast money can go out each month. | D13: v0.2
A14: 10 | B14: Are defaulted loans written off at maturity, or chased into the next year (recoveries)? | C14: Recoveries would add money back to the corpus later. | D14: v0.2
A15: 11 | B15: Who should be able to edit the 'PAMOJA Model Inputs' GUI, and does each district need its own editor? | C15: The GUI page is currently shared only with its owner; wider access needs a deliberate share decision. | D15: v0.3
A16: 12 | B16: What should the risk share of defaults between TAMISEMI and the lender actually be, and should it vary by lender or by performance? Should the lender ever keep part of the repaid principal instead of returning all of it to TAMISEMI? | C16: Placeholders now: TAMISEMI absorbs 50% of every default, the lender the other 50%; the lender returns 100% of repaid principal to TAMISEMI. Matches question 12 on the flowchart (trigger and timing of risk share are still open). | D16: v0.4
... A19: 15 | B19: Should recycled repayments be capped at what the district can still use (CMGs not yet served), or can they always be redeployed even if it means lending to the same CMGs again? | C19: In the placeholder run, once a district's CMGs are all appraised, recycled cash sits idle in the pool - see 'District timeline' for District 1. | D19: v0.5

Sheet Glossary
A1: Glossary
A2: Acronyms and terms used in this model.
A4: Term | B4: Meaning
A5: Advance | B5: Money TAMISEMI sends a lender ahead of lending, based on the CMG pool allocated to that lender.
A6: Allocation | B6: The share of the lending corpus given to a district, based on its loan demand.
A7: Annual cycle | B7: The CMG's savings year. Loans must be repaid before the share-out at the end.
A8: Appraisal | B8: A lender's check of a CMG before deciding whether to lend, and how much. Capacity-limited on 'District timeline' (CMGs a lender can appraise per week).
A9: Break-even default rate | B9: The highest default rate the default budget and TAMISEMI's risk share can cover and still restore the corpus.
A10: CMG | B10: Community Microfinance Group: a savings group whose members save and lend to each other.
A11: Committed tranche | B11: On 'Corpus rollout': the share of a district's allocation advanced upfront, per the tranche % input.
A12: Conversion rate | B12: On the pilot-district sheets: the share of appraised CMGs that are approved and go on to accept the loan.
A13: Corpus | B13: The pool of money available to lend ($24m less the $4m set aside for incentives). The pilot-district sheets use a separate, smaller placeholder pool.
A14: Default | B14: A loan, or part of a loan, that is not repaid.
A15: Default budget / loss reserve | B15: The share of interest set aside to cover TAMISEMI's risk share of defaults.
... A40: TZS / USD | B40: Tanzanian shilling / United States dollar.
